from django.test import TestCase
from django.conf import settings
from restclients.o365.user import User
from restclients.exceptions import DataFailureException

class O365TestUser(TestCase):

    def test_user_info(self):
        with self.settings(
                RESTCLIENTS_PWS_DAO_CLASS='restclients.dao_implementation.o365.File'):

            user = User()
            u = user.get_user('javerage')
            self.assertEquals(len(u.assigned_plans), 7)
            self.assertEquals(u.user_principal_name, 'javerage@dogfood.com')

            u = user.get_user_by_netid('javerage')
            self.assertEquals(u.dir_sync_enabled, True)
            self.assertEquals(len(u.assigned_plans), 0)
            self.assertEquals(len(u.assigned_licenses), 0)
            self.assertEquals(u.mail_nick_name, 'javerage')
